<?xml version="1.0" ?>
<robot name="StickBot_1">
  <!--Joints-->
  <joint name="base_link_to_a_2132_01_5Z_0" type="fixed">
    <parent link="base_link"/>
    <child link="a_2132_01_5Z_0"/>
  </joint>
  <joint name="a_2132_01_5Z_0_to_pp_2084_01_0" type="fixed">
    <parent link="a_2132_01_5Z_0"/>
    <child link="pp_2084_01_0"/>
    <origin rpy="0.0 -3.57068198074e-17 0.0" xyz="-5.78648230435e-16 -0.0375 0.0589153"/>
  </joint>
  <joint name="pp_2084_01_0_to_pp_2084_01_1" type="fixed">
    <parent link="pp_2084_01_0"/>
    <child link="pp_2084_01_1"/>
    <origin rpy="0.0 -0.0 6.22674078412e-50" xyz="8.12409083276e-19 -8.20472662559e-19 0.021"/>
  </joint>
  <joint name="a_2132_01_5Z_0_to_a_2043_01_0" type="fixed">
    <parent link="a_2132_01_5Z_0"/>
    <child link="a_2043_01_0"/>
    <origin rpy="0.0 -3.37465499326e-15 -6.12323399574e-17" xyz="-3.99679288865e-18 0.07 0.1317625"/>
  </joint>
  <joint name="a_2043_01_0_to_hebi_x8_16_20Z_0" type="fixed">
    <parent link="a_2043_01_0"/>
    <child link="hebi_x8_16_20Z_0"/>
    <origin rpy="0.0 -6.12323399574e-17 -3.14159265359" xyz="-2.68108607925e-17 -1.65959587488e-33 0.0047752"/>
  </joint>
  <joint name="Turret/Base/X8_16" type="revolute">
    <parent link="hebi_x8_16_20Z_0"/>
    <child link="a_2074_01_13Z_0"/>
    <origin rpy="0.0 1.18329135783e-30 -3.14159265359" xyz="-1.08634158951e-24 -2.84217094304e-17 0.04505"/>
    <axis xyz="-7.88860905221e-31 6.12323399574e-17 1.0"/>
    <dynamics damping="0.5" friction="0.06"/>
    <limit effort="100" lower="-2.14e9" upper="+2.14e9" velocity="100"/>
  </joint>
  <gazebo reference="Turret/Base/X8_16">
    <implicitSpringDamper>True</implicitSpringDamper>
  </gazebo>
  <joint name="a_2074_01_13Z_0_to_tubepar_19Z_0" type="fixed">
    <parent link="a_2074_01_13Z_0"/>
    <child link="tubepar_19Z_0"/>
    <origin rpy="-1.57079632679 -0.0 5.67339602409e-33" xyz="1.31411562278e-17 1.85506515547e-16 0.0125"/>
  </joint>
  <joint name="tubepar_19Z_0_to_a_2089_01_14Z_0" type="fixed">
    <parent link="tubepar_19Z_0"/>
    <child link="a_2089_01_14Z_0"/>
    <origin rpy="-6.12323399574e-17 -0.0 1.57079632679" xyz="2.01948391737e-31 -0.425 1.12103877146e-47"/>
  </joint>
  <joint name="a_2089_01_14Z_0_to_hebi_x8_16_12Z_0" type="fixed">
    <parent link="a_2089_01_14Z_0"/>
    <child link="hebi_x8_16_12Z_0"/>
    <origin rpy="3.14159265359 -1.18329136e-30 0.0" xyz="-0.014 -1.07158121718e-18 -0.02"/>
  </joint>
  <joint name="Arm/Shoulder/X8_16" type="revolute">
    <parent link="hebi_x8_16_12Z_0"/>
    <child link="a_2038_02_11Z_0"/>
    <origin rpy="1.51632209646e-62 1.18329136e-30 3.14159265359" xyz="-1.40799588069e-31 -2.91639355579e-17 0.04505"/>
    <axis xyz="-2.02888622329e-31 7.64209001933e-30 1.0"/>
    <dynamics damping="0.5" friction="0.06"/>
    <limit effort="100" lower="-2.14e9" upper="+2.14e9" velocity="100"/>
  </joint>
  <gazebo reference="Arm/Shoulder/X8_16">
    <implicitSpringDamper>True</implicitSpringDamper>
  </gazebo>
  <joint name="a_2038_02_11Z_0_to_tubepar_4Z_0" type="fixed">
    <parent link="a_2038_02_11Z_0"/>
    <child link="tubepar_4Z_0"/>
    <origin rpy="1.57079632679 -1.57079632679 0.0" xyz="0.0135 1.35017697283e-18 0.02"/>
  </joint>
  <joint name="tubepar_4Z_0_to_a_2039_02_9Z_0" type="fixed">
    <parent link="tubepar_4Z_0"/>
    <child link="a_2039_02_9Z_0"/>
    <origin rpy="1.57079632679 2.50240867501e-14 -1.57079632679" xyz="-2.18952885051e-47 -0.25 -9.99999998558e-24"/>
  </joint>
  <joint name="a_2039_02_9Z_0_to_hebi_x5_9_10Z_0" type="fixed">
    <parent link="a_2039_02_9Z_0"/>
    <child link="hebi_x5_9_10Z_0"/>
    <origin rpy="1.22464679915e-16 1.04083409e-17 2.50240867501e-14" xyz="0.014 3.34009046003e-16 0.02"/>
  </joint>
  <joint name="Arm/Elbow/X5_9" type="revolute">
    <parent link="hebi_x5_9_10Z_0"/>
    <child link="a_2038_02_17Z_0"/>
    <origin rpy="2.0448405016e-48 -2.77555756e-17 0.0" xyz="-3.23178984945e-19 -3.14850699177e-18 0.03105"/>
    <axis xyz="1.73472347e-17 5.71153784307e-30 1.0"/>
    <dynamics damping="0.6" friction="0.06"/>
    <limit effort="100" lower="-2.14e9" upper="+2.14e9" velocity="100"/>
  </joint>
  <gazebo reference="Arm/Elbow/X5_9">
    <implicitSpringDamper>True</implicitSpringDamper>
  </gazebo>
  <joint name="a_2038_02_17Z_0_to_tubepar_18Z_0" type="fixed">
    <parent link="a_2038_02_17Z_0"/>
    <child link="tubepar_18Z_0"/>
    <origin rpy="1.57079632679 -1.57079632679 0.0" xyz="0.0135 1.11373125466e-19 0.02"/>
  </joint>
  <joint name="tubepar_18Z_0_to_a_2119_01_15Z_0" type="fixed">
    <parent link="tubepar_18Z_0"/>
    <child link="a_2119_01_15Z_0"/>
    <origin rpy="1.57079632679 -4.58591992252e-48 0.0" xyz="2.7686186826e-18 -0.25 -1.00000003895e-23"/>
  </joint>
  <joint name="a_2119_01_15Z_0_to_hebi_x5_1_8Z_0" type="fixed">
    <parent link="a_2119_01_15Z_0"/>
    <child link="hebi_x5_1_8Z_0"/>
    <origin rpy="0.0 1.04083409e-17 -2.37066402887e-33" xyz="-2.255140511e-19 7.96030419446e-19 0.013"/>
  </joint>
  <joint name="Gripper/Wrist/X5_1" type="revolute">
    <parent link="hebi_x5_1_8Z_0"/>
    <child link="GRIPPER_CORE_0"/>
    <origin rpy="1.57079632679 2.77555756e-17 3.14159265359" xyz="-5.77052294832e-17 -3.14850699177e-18 0.03105"/>
    <axis xyz="-1.23259516441e-32 1.0 -2.09048139884e-29"/>
    <dynamics damping="0.5" friction="0.06"/>
    <limit effort="100" lower="-2.14e9" upper="+2.14e9" velocity="100"/>
  </joint>
  <gazebo reference="Gripper/Wrist/X5_1">
    <implicitSpringDamper>True</implicitSpringDamper>
  </gazebo>
  <joint name="Gripper_Joint_2" type="revolute">
    <parent link="GRIPPER_CORE_0"/>
    <child link="pm_2221_01_2_0"/>
    <origin rpy="3.14159265359 -0.0 3.14159265359" xyz="-0.0125 0.0115 2.19793342467e-19"/>
    <axis xyz="-4.0841087401e-47 -3.3134226533e-15 1.0"/>
    <dynamics damping="0.5" friction="0.06"/>
    <limit effort="100" lower="-2e6" upper="+2e6" velocity="100"/>
  </joint>
  <gazebo reference="Gripper_Joint_2">
    <implicitSpringDamper>True</implicitSpringDamper>
  </gazebo>
  <joint name="pm_2221_01_2_0_to_pm_2371_01_1_0" type="fixed">
    <parent link="pm_2221_01_2_0"/>
    <child link="pm_2371_01_1_0"/>
    <origin rpy="3.14159265359 6.12323399574e-17 1.57079632679" xyz="0.03 -1.05409565011e-34 -7.97872810003e-20"/>
  </joint>
  <joint name="Gripper_Joint_1" type="revolute">
    <parent link="GRIPPER_CORE_0"/>
    <child link="pm_2221_01_2_1"/>
    <origin rpy="0.0 -0.0 0.0" xyz="0.0125 0.0115 1.11379248701e-19"/>
    <axis xyz="-4.0841087401e-47 3.3134226533e-15 1.0"/>
    <dynamics damping="0.5" friction="0.06"/>
    <limit effort="100" lower="-2e6" upper="+2e6" velocity="100"/>
  </joint>
  <gazebo reference="Gripper_Joint_1">
    <implicitSpringDamper>True</implicitSpringDamper>
  </gazebo>
  <joint name="pm_2221_01_2_1_to_pm_2371_01_1_1" type="fixed">
    <parent link="pm_2221_01_2_1"/>
    <child link="pm_2371_01_1_1"/>
    <origin rpy="3.14159265359 6.12323399574e-17 1.57079632679" xyz="0.03 6.34213802085e-34 7.98072809997e-20"/>
  </joint>
  <joint name="tubepar_19Z_0_to_a_2089_01_6Z_0" type="fixed">
    <parent link="tubepar_19Z_0"/>
    <child link="a_2089_01_6Z_0"/>
    <origin rpy="-3.14159265359 -0.0 1.57079632679" xyz="2.01948391737e-31 -0.5 0.0"/>
  </joint>
  <joint name="a_2089_01_6Z_0_to_hebi_x5_9_7Z_0" type="fixed">
    <parent link="a_2089_01_6Z_0"/>
    <child link="hebi_x5_9_7Z_0"/>
    <origin rpy="-3.14159265359 -1.04083409e-17 3.14159265359" xyz="-0.014 -1.07158121718e-18 -0.02"/>
  </joint>
  <joint name="a_2132_01_5Z_0_to_a_2043_01_1" type="fixed">
    <parent link="a_2132_01_5Z_0"/>
    <child link="a_2043_01_1"/>
    <origin rpy="-1.57079632679 1.57079632679 0.0" xyz="0.13 0.1778 -0.025400756766"/>
  </joint>
  <joint name="a_2043_01_1_to_hebi_x8_16_2Z_0" type="fixed">
    <parent link="a_2043_01_1"/>
    <child link="hebi_x8_16_2Z_0"/>
    <origin rpy="1.49975978266e-32 -6.12323399574e-17 3.14159265359" xyz="4.67700711639e-17 9.38208807873e-16 0.0047752"/>
  </joint>
  <joint name="DiffDriveBase/FrontLeft/X8_16" type="revolute">
    <parent link="hebi_x8_16_2Z_0"/>
    <child link="pm_2155_01_0"/>
    <origin rpy="-7.49879891331e-33 1.18329135783e-30 3.14159265359" xyz="-2.75851691508e-18 -1.73288773498e-16 0.04505"/>
    <axis xyz="6.12323399574e-17 6.12323399574e-17 1.0"/>
    <dynamics damping="0.5" friction="0.06"/>
    <limit effort="100" lower="-2.14e9" upper="+2.14e9" velocity="100"/>
  </joint>
  <gazebo reference="DiffDriveBase/FrontLeft/X8_16">
    <implicitSpringDamper>True</implicitSpringDamper>
  </gazebo>
  <joint name="pm_2155_01_0_to_pp_2074_08_0" type="fixed">
    <parent link="pm_2155_01_0"/>
    <child link="pp_2074_08_0"/>
    <origin rpy="6.30106823421e-15 5.72153003001e-15 -0.78539816407" xyz="5.51091059616e-19 1.14237928781e-16 0.009"/>
  </joint>
  <joint name="a_2132_01_5Z_0_to_a_2043_01_2" type="fixed">
    <parent link="a_2132_01_5Z_0"/>
    <child link="a_2043_01_2"/>
    <origin rpy="1.57079632679 1.57079632679 0.0" xyz="-0.13 -0.1778 -0.023190956766"/>
  </joint>
  <joint name="a_2043_01_2_to_DiffDriveBase/RearRight" type="fixed">
    <parent link="a_2043_01_2"/>
    <child link="DiffDriveBase/RearRight"/>
    <origin rpy="-1.49975978266e-32 -6.12323399574e-17 3.14159265359" xyz="-6.52063401807e-18 8.5557524961e-17 0.0047752"/>
  </joint>
  <joint name="DiffDriveBase/RearRight" type="continuous">
    <parent link="DiffDriveBase/RearRight"/>
    <child link="pm_2155_01_1"/>
    <origin rpy="7.49879891331e-33 1.18329135783e-30 3.14159265359" xyz="-2.75851691508e-18 -3.11802263455e-17 0.04505"/>
    <axis xyz="6.12323399574e-17 6.12323399574e-17 1.0"/>
    <dynamics damping="0.5" friction="0.06"/>
    <limit effort="20" velocity="30"/>
    <dynamics damping="0.5" friction="0.5"/>
  </joint>
  <gazebo reference="DiffDriveBase/RearRight">
    <implicitSpringDamper>True</implicitSpringDamper>
  </gazebo>
  <joint name="pm_2155_01_1_to_pp_2074_08_1" type="fixed">
    <parent link="pm_2155_01_1"/>
    <child link="pp_2074_08_1"/>
    <origin rpy="-2.75783606318e-15 2.60231890953e-15 -0.785398163616" xyz="4.10380473842e-18 5.51091059616e-19 0.009"/>
  </joint>
  <joint name="a_2132_01_5Z_0_to_a_2043_01_3" type="fixed">
    <parent link="a_2132_01_5Z_0"/>
    <child link="a_2043_01_3"/>
    <origin rpy="-1.57079632679 1.57079632679 0.0" xyz="-0.13 0.1778 -0.025400756766"/>
  </joint>
  <joint name="a_2043_01_3_to_hebi_x8_16_16Z_0" type="fixed">
    <parent link="a_2043_01_3"/>
    <child link="hebi_x8_16_16Z_0"/>
    <origin rpy="-3.31635770885e-45 -6.12323399574e-17 3.14159265359" xyz="4.67700711639e-17 -9.37624014534e-16 0.0047752"/>
  </joint>
  <joint name="DiffDriveBase/RearLeft/X8_16" type="revolute">
    <parent link="hebi_x8_16_16Z_0"/>
    <child link="pm_2155_01_2"/>
    <origin rpy="1.65817885443e-45 1.18329135783e-30 3.14159265359" xyz="-2.75851691508e-18 1.10928320807e-16 0.04505"/>
    <axis xyz="6.12323399574e-17 6.12323399574e-17 1.0"/>
    <dynamics damping="0.5" friction="0.06"/>
    <limit effort="100" lower="-2.14e9" upper="+2.14e9" velocity="100"/>
  </joint>
  <gazebo reference="DiffDriveBase/RearLeft/X8_16">
    <implicitSpringDamper>True</implicitSpringDamper>
  </gazebo>
  <joint name="pm_2155_01_2_to_pp_2074_08_2" type="fixed">
    <parent link="pm_2155_01_2"/>
    <child link="pp_2074_08_2"/>
    <origin rpy="-3.61210627989e-15 6.93336817517e-16 -0.78539816364" xyz="5.51091059616e-19 -1.13135746662e-16 0.009"/>
  </joint>
  <joint name="a_2132_01_5Z_0_to_a_2043_01_4" type="fixed">
    <parent link="a_2132_01_5Z_0"/>
    <child link="a_2043_01_4"/>
    <origin rpy="0.0 -3.37465499326e-15 -6.12323399574e-17" xyz="-1.11022202463e-17 -0.05 0.1317625"/>
  </joint>
  <joint name="a_2043_01_4_to_rplidar_a2_0" type="fixed">
    <parent link="a_2043_01_4"/>
    <child link="rplidar_a2_0"/>
    <origin rpy="0.0 -6.12323399574e-17 -3.14159265359" xyz="-2.70533019508e-17 -1.6744411143e-33 0.0047752"/>
  </joint>
  <joint name="a_2132_01_5Z_0_to_a_2043_01_5" type="fixed">
    <parent link="a_2132_01_5Z_0"/>
    <child link="a_2043_01_5"/>
    <origin rpy="1.57079632679 1.57079632679 0.0" xyz="0.13 -0.1778 -0.023190956766"/>
  </joint>
  <joint name="a_2043_01_5_to_hebi_x8_16_1Z_0" type="fixed">
    <parent link="a_2043_01_5"/>
    <child link="hebi_x8_16_1Z_0"/>
    <origin rpy="-1.49975978266e-32 -6.12323399574e-17 3.14159265359" xyz="-2.96792033927e-18 8.5557524961e-17 0.0047752"/>
  </joint>
  <joint name="DiffDriveBase/FrontRight/X8_16" type="revolute">
    <parent link="hebi_x8_16_1Z_0"/>
    <child link="pm_2155_01_3"/>
    <origin rpy="7.49879891331e-33 1.18329135783e-30 3.14159265359" xyz="-2.75851691508e-18 -3.11802263455e-17 0.04505"/>
    <axis xyz="6.12323399574e-17 6.12323399574e-17 1.0"/>
    <dynamics damping="0.5" friction="0.06"/>
    <limit effort="100" lower="-2.14e9" upper="+2.14e9" velocity="100"/>
  </joint>
  <gazebo reference="DiffDriveBase/FrontRight/X8_16">
    <implicitSpringDamper>True</implicitSpringDamper>
  </gazebo>
  <joint name="pm_2155_01_3_to_pp_2074_08_3" type="fixed">
    <parent link="pm_2155_01_3"/>
    <child link="pp_2074_08_3"/>
    <origin rpy="6.83855313154e-16 4.65623150509e-15 -0.785398163616" xyz="5.51091059616e-19 5.51091059616e-19 0.009"/>
  </joint>
  <!--Links-->
  <link name="base_link">
    <!--Transformation from CyPhy2CAD global reference frame to base_link-->
    <CyPhy2CAD>
      <CADAssembly_metrics>
        <RotationMatrix>
          <Row>
            <Column Value="1.0"/>
            <Column Value="0.0"/>
            <Column Value="0.0"/>
          </Row>
          <Row>
            <Column Value="0.0"/>
            <Column Value="1.0"/>
            <Column Value="0.0"/>
          </Row>
          <Row>
            <Column Value="0.0"/>
            <Column Value="0.0"/>
            <Column Value="1.0"/>
          </Row>
        </RotationMatrix>
        <Translation X="1e-20" Y="1e-20" Z="1e-20"/>
      </CADAssembly_metrics>
    </CyPhy2CAD>
  </link>
  <link name="pm_2155_01_0">
    <visual>
      <origin rpy="0 0 0" xyz="-0.00099182129 -0.0071643037 -0.000236828"/>
      <geometry>
        <mesh filename="package://stickbot_generated_urdf/meshes/pm_2155_01_prt.stl" scale="0.001 0.001 0.001"/>
      </geometry>
    </visual>
    <collision>
      <origin rpy="0 0 0" xyz="-0.00099182129 -0.0071643037 -0.000236828"/>
      <geometry>
        <mesh filename="package://stickbot_generated_urdf/meshes/pm_2155_01_prt.stl" scale="0.001 0.001 0.001"/>
      </geometry>
    </collision>
    <inertial>
      <origin rpy="0 0 0" xyz="1.34037442319e-07 1.11051366795e-07 0.00499989583184"/>
      <mass value="0.052674179644478125"/>
      <inertia ixx="1.14786537077e-05" ixy="0.0" ixz="0.0" iyy="1.14786271535e-05" iyz="0.0" izz="2.18768701014e-05"/>
    </inertial>
  </link>
  <gazebo reference="pm_2155_01_0">
    <selfCollide>True</selfCollide>
    <material>Gazebo/Grey</material>
    <mu1>0.1</mu1>
    <mu2>0.1</mu2>
    <kp>10000000</kp>
    <kd>1</kd>
    <minDepth>0</minDepth>
    <maxVel>100</maxVel>
  </gazebo>
  <link name="a_2043_01_2">
    <visual>
      <origin rpy="0 0 0" xyz="-6.52063401807e-18 8.5557524961e-17 0.0047752"/>
      <geometry>
        <mesh filename="package://stickbot_generated_urdf/meshes/a_2043_01_prt.stl" scale="0.001 0.001 0.001"/>
      </geometry>
    </visual>
    <collision>
      <origin rpy="0 0 0" xyz="-6.52063401807e-18 8.5557524961e-17 0.0047752"/>
      <geometry>
        <mesh filename="package://stickbot_generated_urdf/meshes/a_2043_01_prt.stl" scale="0.001 0.001 0.001"/>
      </geometry>
    </collision>
    <inertial>
      <origin rpy="0 0 0" xyz="0.00139419949295 8.5557524961e-17 0.00184329510899"/>
      <mass value="0.06272938391183215"/>
      <inertia ixx="7.22571415296e-05" ixy="2.96268938105e-10" ixz="-5.68510520871e-08" iyy="1.34631068457e-05" iyz="0.0" izz="8.48613385518e-05"/>
    </inertial>
  </link>
  <gazebo reference="a_2043_01_2">
    <selfCollide>True</selfCollide>
    <material>Gazebo/Black</material>
    <mu1>0.1</mu1>
    <mu2>0.1</mu2>
    <kp>10000000</kp>
    <kd>1</kd>
    <minDepth>0.0005</minDepth>
    <maxVel>100</maxVel>
  </gazebo>
  <link name="tubepar_18Z_0">
    <visual>
      <origin rpy="0 0 0" xyz="2.7686186826e-18 -0.25 -1.61232343584e-23"/>
      <geometry>
        <mesh filename="package://stickbot_generated_urdf/meshes/tubepar_18z_prt.stl" scale="0.001 0.001 0.001"/>
      </geometry>
    </visual>
    <collision>
      <origin rpy="0 0 0" xyz="2.7686186826e-18 -0.25 -1.61232343584e-23"/>
      <geometry>
        <mesh filename="package://stickbot_generated_urdf/meshes/tubepar_18z_prt.stl" scale="0.001 0.001 0.001"/>
      </geometry>
    </collision>
    <inertial>
      <origin rpy="0 0 0" xyz="2.7686186826e-18 -0.125 -1.61232343584e-23"/>
      <mass value="0.10111189399303355"/>
      <inertia ixx="0.000538058313062" ixy="0.0" ixz="0.0" iyy="2.28677545314e-05" iyz="0.0" izz="0.00053805833723"/>
    </inertial>
  </link>
  <gazebo reference="tubepar_18Z_0">
    <selfCollide>True</selfCollide>
    <material>Gazebo/Grey</material>
    <mu1>0.05</mu1>
    <mu2>0.05</mu2>
    <kp>10000000</kp>
    <kd>1</kd>
    <minDepth>0.0005</minDepth>
    <maxVel>100</maxVel>
  </gazebo>
  <link name="a_2038_02_11Z_0">
    <visual>
      <origin rpy="0 0 0" xyz="4.47370696773e-33 1.35017697283e-18 -3.91812418982e-79"/>
      <geometry>
        <mesh filename="package://stickbot_generated_urdf/meshes/a_2038_02_11z_prt.stl" scale="0.001 0.001 0.001"/>
      </geometry>
    </visual>
    <collision>
      <origin rpy="0 0 0" xyz="4.47370696773e-33 1.35017697283e-18 -3.91812418982e-79"/>
      <geometry>
        <mesh filename="package://stickbot_generated_urdf/meshes/a_2038_02_11z_prt.stl" scale="0.001 0.001 0.001"/>
      </geometry>
    </collision>
    <inertial>
      <origin rpy="0 0 0" xyz="0.0176052907699 1.35017697283e-18 0.0142788404199"/>
      <mass value="0.059108249978877175"/>
      <inertia ixx="2.3632587043e-05" ixy="0.0" ixz="-3.93131579939e-06" iyy="2.03298829586e-05" iyz="0.0" izz="2.72912531732e-05"/>
    </inertial>
  </link>
  <gazebo reference="a_2038_02_11Z_0">
    <selfCollide>True</selfCollide>
    <material>Gazebo/Black</material>
    <mu1>0.1</mu1>
    <mu2>0.1</mu2>
    <kp>10000000</kp>
    <kd>1</kd>
    <minDepth>0.0005</minDepth>
    <maxVel>100</maxVel>
  </gazebo>
  <link name="pp_2074_08_3">
    <visual>
      <origin rpy="0 0 0" xyz="3.22410558223e-12 8.3502854391e-12 0.03175"/>
      <geometry>
        <mesh filename="package://stickbot_generated_urdf/meshes/pp_2074_08_prt.stl" scale="0.001 0.001 0.001"/>
      </geometry>
    </visual>
    <collision>
      <origin rpy="0 0 0" xyz="3.22410558223e-12 8.3502854391e-12 0.03175"/>
      <geometry>
        <mesh filename="package://stickbot_generated_urdf/meshes/pp_2074_08_prt.stl" scale="0.001 0.001 0.001"/>
      </geometry>
    </collision>
    <inertial>
      <origin rpy="0 0 0" xyz="-5.78059029415e-07 4.17617013729e-07 0.0190499354094"/>
      <mass value="0.7635860425050807"/>
      <inertia ixx="0.002680677325" ixy="0.0" ixz="0.0" iyy="0.00268067446492" iyz="0.0" izz="0.00527682335031"/>
    </inertial>
  </link>
  <gazebo reference="pp_2074_08_3">
    <selfCollide>True</selfCollide>
    <material>Gazebo/Black</material>
    <mu1>0.7</mu1>
    <mu2>0.7</mu2>
    <kp>1000000</kp>
    <kd>1</kd>
    <minDepth>0.001</minDepth>
    <maxVel>50</maxVel>
  </gazebo>
  <link name="a_2089_01_6Z_0">
    <visual>
      <origin rpy="0 0 0" xyz="-0.014 -1.07158121718e-18 -0.0175"/>
      <geometry>
        <mesh filename="package://stickbot_generated_urdf/meshes/a_2089_01_6z_prt.stl" scale="0.001 0.001 0.001"/>
      </geometry>
    </visual>
    <collision>
      <origin rpy="0 0 0" xyz="-0.014 -1.07158121718e-18 -0.0175"/>
      <geometry>
        <mesh filename="package://stickbot_generated_urdf/meshes/a_2089_01_6z_prt.stl" scale="0.001 0.001 0.001"/>
      </geometry>
    </collision>
    <inertial>
      <origin rpy="0 0 0" xyz="-0.0141834319891 1.2390345004e-07 -0.00675469816879"/>
      <mass value="0.13694950430241026"/>
      <inertia ixx="6.44476746049e-05" ixy="0.0" ixz="2.64849744516e-08" iyy="8.71842240473e-05" iyz="0.0" izz="0.000115762185767"/>
    </inertial>
  </link>
  <gazebo reference="a_2089_01_6Z_0">
    <selfCollide>True</selfCollide>
    <material>Gazebo/Grey</material>
    <mu1>0.1</mu1>
    <mu2>0.1</mu2>
    <kp>10000000</kp>
    <kd>1</kd>
    <minDepth>0.0005</minDepth>
    <maxVel>100</maxVel>
  </gazebo>
  <link name="pm_2155_01_1">
    <visual>
      <origin rpy="0 0 0" xyz="-0.00099182129 -0.0071643037 -0.000236828"/>
      <geometry>
        <mesh filename="package://stickbot_generated_urdf/meshes/pm_2155_01_prt.stl" scale="0.001 0.001 0.001"/>
      </geometry>
    </visual>
    <collision>
      <origin rpy="0 0 0" xyz="-0.00099182129 -0.0071643037 -0.000236828"/>
      <geometry>
        <mesh filename="package://stickbot_generated_urdf/meshes/pm_2155_01_prt.stl" scale="0.001 0.001 0.001"/>
      </geometry>
    </collision>
    <inertial>
      <origin rpy="0 0 0" xyz="1.34037442321e-07 1.11051366681e-07 0.00499989583184"/>
      <mass value="0.052674179644478125"/>
      <inertia ixx="1.14786537077e-05" ixy="0.0" ixz="0.0" iyy="1.14786271535e-05" iyz="0.0" izz="2.18768701014e-05"/>
    </inertial>
  </link>
  <gazebo reference="pm_2155_01_1">
    <selfCollide>True</selfCollide>
    <material>Gazebo/Grey</material>
    <mu1>0.1</mu1>
    <mu2>0.1</mu2>
    <kp>10000000</kp>
    <kd>1</kd>
    <minDepth>0</minDepth>
    <maxVel>100</maxVel>
  </gazebo>
  <link name="hebi_x5_9_10Z_0">
    <visual>
      <origin rpy="0 0 0" xyz="-1.561251135e-19 -2.49799181e-18 0.015"/>
      <geometry>
        <mesh filename="package://stickbot_generated_urdf/meshes/hebi_x5_9_10z_prt.stl" scale="0.001 0.001 0.001"/>
      </geometry>
    </visual>
    <collision>
      <origin rpy="0 0 0" xyz="-1.561251135e-19 -2.49799181e-18 0.015"/>
      <geometry>
        <mesh filename="package://stickbot_generated_urdf/meshes/hebi_x5_9_10z_prt.stl" scale="0.001 0.001 0.001"/>
      </geometry>
    </collision>
    <inertial>
      <origin rpy="0 0 0" xyz="-0.0142019322139 -0.00151173442654 0.0150064707722"/>
      <mass value="0.3601223934133934"/>
      <inertia ixx="0.000149654657264" ixy="-2.029262623e-05" ixz="1.36324075072e-08" iyy="0.000259599603648" iyz="1.37817063293e-07" izz="0.000355190384437"/>
    </inertial>
  </link>
  <gazebo reference="hebi_x5_9_10Z_0">
    <selfCollide>True</selfCollide>
    <material>Gazebo/Red</material>
    <mu1>0.1</mu1>
    <mu2>0.1</mu2>
    <kp>10000000</kp>
    <kd>1</kd>
    <minDepth>0.001</minDepth>
    <maxVel>100</maxVel>
    <sensor name="Arm/Elbow/imu_sensor" type="imu">
      <always_on>true</always_on>
      <update_rate>100</update_rate>
      <visualize>true</visualize>
      <plugin filename="libgazebo_ros_imu_sensor.so" name="imu_plugin">
        <topicName>/hebiros_gazebo_plugin/imu/Arm/Elbow</topicName>
        <bodyName>Arm/Elbow/imu_link</bodyName>
        <updateRateHZ>10.0</updateRateHZ>
        <gaussianNoise>0.0</gaussianNoise>
        <xyzOffset>0.025 0 0.003</xyzOffset>
        <rpyOffset>0 0 0</rpyOffset>
        <frameName>Arm/Elbow/imu_link</frameName>
      </plugin>
      <pose>0 0 0 0 0 0</pose>
    </sensor>
  </gazebo>
  <link name="GRIPPER_CORE_0">
    <visual>
      <origin rpy="0 0 0" xyz="-5.68434188608e-17 7.28268239974e-34 2.19793342467e-19"/>
      <geometry>
        <mesh filename="package://stickbot_generated_urdf/meshes/gripper_core_prt.stl" scale="0.001 0.001 0.001"/>
      </geometry>
    </visual>
    <collision>
      <origin rpy="0 0 0" xyz="-5.68434188608e-17 7.28268239974e-34 2.19793342467e-19"/>
      <geometry>
        <mesh filename="package://stickbot_generated_urdf/meshes/gripper_core_prt.stl" scale="0.001 0.001 0.001"/>
      </geometry>
    </collision>
    <inertial>
      <origin rpy="0 0 0" xyz="-5.68434188608e-17 0.00701204083451 2.19793342467e-19"/>
      <mass value="0.07306201103685102"/>
      <inertia ixx="1.28870526185e-05" ixy="0.0" ixz="0.0" iyy="1.41257455022e-05" iyz="0.0" izz="1.18996295578e-05"/>
    </inertial>
  </link>
  <gazebo reference="GRIPPER_CORE_0">
    <selfCollide>True</selfCollide>
    <material>Gazebo/Grey</material>
    <mu1>0.05</mu1>
    <mu2>0.05</mu2>
    <kp>10000000</kp>
    <kd>1</kd>
    <minDepth>0.0005</minDepth>
    <maxVel>100</maxVel>
  </gazebo>
  <link name="a_2074_01_13Z_0">
    <visual>
      <origin rpy="0 0 0" xyz="-4.41762106924e-32 5.58606398045e-17 -0.01605"/>
      <geometry>
        <mesh filename="package://stickbot_generated_urdf/meshes/a_2074_01_13z_prt.stl" scale="0.001 0.001 0.001"/>
      </geometry>
    </visual>
    <collision>
      <origin rpy="0 0 0" xyz="-4.41762106924e-32 5.58606398045e-17 -0.01605"/>
      <geometry>
        <mesh filename="package://stickbot_generated_urdf/meshes/a_2074_01_13z_prt.stl" scale="0.001 0.001 0.001"/>
      </geometry>
    </collision>
    <inertial>
      <origin rpy="0 0 0" xyz="0.00396895473481 5.58606398045e-17 0.0148168983831"/>
      <mass value="0.09157149120222269"/>
      <inertia ixx="3.1887902612e-05" ixy="0.0" ixz="-1.15786238257e-06" iyy="2.62794552352e-05" iyz="0.0" izz="3.69392561661e-05"/>
    </inertial>
  </link>
  <gazebo reference="a_2074_01_13Z_0">
    <selfCollide>True</selfCollide>
    <material>Gazebo/Grey</material>
    <mu1>0.1</mu1>
    <mu2>0.1</mu2>
    <kp>10000000</kp>
    <kd>1</kd>
    <minDepth>0.0005</minDepth>
    <maxVel>100</maxVel>
  </gazebo>
  <link name="hebi_x5_1_8Z_0">
    <visual>
      <origin rpy="0 0 0" xyz="-5.72597524948e-17 -2.49799181e-18 0.015"/>
      <geometry>
        <mesh filename="package://stickbot_generated_urdf/meshes/hebi_x5_1_8z_prt.stl" scale="0.001 0.001 0.001"/>
      </geometry>
    </visual>
    <collision>
      <origin rpy="0 0 0" xyz="-5.72597524948e-17 -2.49799181e-18 0.015"/>
      <geometry>
        <mesh filename="package://stickbot_generated_urdf/meshes/hebi_x5_1_8z_prt.stl" scale="0.001 0.001 0.001"/>
      </geometry>
    </collision>
    <inertial>
      <origin rpy="0 0 0" xyz="-0.0142019322139 -0.00151173442654 0.0150064707722"/>
      <mass value="0.31314990731599424"/>
      <inertia ixx="0.000130134484577" ixy="-1.76457619391e-05" ixz="1.18542673976e-08" iyy="0.00022573878578" iyz="1.19840924602e-07" izz="0.000308861203858"/>
    </inertial>
  </link>
  <gazebo reference="hebi_x5_1_8Z_0">
    <selfCollide>True</selfCollide>
    <material>Gazebo/Red</material>
    <mu1>0.1</mu1>
    <mu2>0.1</mu2>
    <kp>10000000</kp>
    <kd>1</kd>
    <minDepth>0.001</minDepth>
    <maxVel>100</maxVel>
    <sensor name="Gripper/Wrist/imu_sensor" type="imu">
      <always_on>true</always_on>
      <update_rate>100</update_rate>
      <visualize>true</visualize>
      <plugin filename="libgazebo_ros_imu_sensor.so" name="imu_plugin">
        <topicName>/hebiros_gazebo_plugin/imu/Gripper/Wrist</topicName>
        <bodyName>Gripper/Wrist/imu_link</bodyName>
        <updateRateHZ>10.0</updateRateHZ>
        <gaussianNoise>0.0</gaussianNoise>
        <xyzOffset>0.025 0 0.003</xyzOffset>
        <rpyOffset>0 0 0</rpyOffset>
        <frameName>Gripper/Wrist/imu_link</frameName>
      </plugin>
      <pose>0 0 0 0 0 0</pose>
    </sensor>
  </gazebo>
  <link name="pp_2074_08_1">
    <visual>
      <origin rpy="0 0 0" xyz="-3.22450467029e-12 -8.35106996524e-12 0.03175"/>
      <geometry>
        <mesh filename="package://stickbot_generated_urdf/meshes/pp_2074_08_prt.stl" scale="0.001 0.001 0.001"/>
      </geometry>
    </visual>
    <collision>
      <origin rpy="0 0 0" xyz="-3.22450467029e-12 -8.35106996524e-12 0.03175"/>
      <geometry>
        <mesh filename="package://stickbot_generated_urdf/meshes/pp_2074_08_prt.stl" scale="0.001 0.001 0.001"/>
      </geometry>
    </collision>
    <inertial>
      <origin rpy="0 0 0" xyz="-5.78065478025e-07 4.17600312374e-07 0.0190499354094"/>
      <mass value="0.7635860425050807"/>
      <inertia ixx="0.002680677325" ixy="0.0" ixz="0.0" iyy="0.00268067446492" iyz="0.0" izz="0.00527682335031"/>
    </inertial>
  </link>
  <gazebo reference="pp_2074_08_1">
    <selfCollide>True</selfCollide>
    <material>Gazebo/Black</material>
    <mu1>0.7</mu1>
    <mu2>0.7</mu2>
    <kp>1000000</kp>
    <kd>1</kd>
    <minDepth>0.001</minDepth>
    <maxVel>50</maxVel>
  </gazebo>
  <link name="DiffDriveBase/RearRight">
    <visual>
      <origin rpy="0 0 0" xyz="-1.56191985342e-17 -1.40834381902e-18 0.023"/>
      <geometry>
        <mesh filename="package://stickbot_generated_urdf/meshes/hebi_x8_16_3z_prt.stl" scale="0.001 0.001 0.001"/>
      </geometry>
    </visual>
    <collision>
      <origin rpy="0 0 0" xyz="-1.56191985342e-17 -1.40834381902e-18 0.023"/>
      <geometry>
        <mesh filename="package://stickbot_generated_urdf/meshes/hebi_x8_16_3z_prt.stl" scale="0.001 0.001 0.001"/>
      </geometry>
    </collision>
    <inertial>
      <origin rpy="0 0 0" xyz="0.014563817146 0.00162514634779 0.0219127754611"/>
      <mass value="5.000268491400921"/>
      <inertia ixx="0.00252497997304" ixy="-0.000307494501523" ixz="2.34381592723e-05" iyy="0.00412897878772" iyz="6.0494430943e-06" izz="0.0050506140471"/>
    </inertial>
  </link>
  <gazebo reference="DiffDriveBase/RearRight">
    <selfCollide>True</selfCollide>
    <material>Gazebo/Red</material>
    <mu1>0.1</mu1>
    <mu2>0.1</mu2>
    <kp>10000000</kp>
    <kd>1</kd>
    <minDepth>0.001</minDepth>
    <maxVel>100</maxVel>
    <sensor name="DiffDriveBase/RearRight/imu_sensor" type="imu">
      <always_on>true</always_on>
      <update_rate>100</update_rate>
      <visualize>true</visualize>
      <plugin filename="libgazebo_ros_imu_sensor.so" name="imu_plugin">
        <topicName>/hebiros_gazebo_plugin/imu/DiffDriveBase/RearRight</topicName>
        <bodyName>DiffDriveBase/RearRight/imu_link</bodyName>
        <updateRateHZ>10.0</updateRateHZ>
        <gaussianNoise>0.0</gaussianNoise>
        <xyzOffset>0.025 0 0.003</xyzOffset>
        <rpyOffset>0 0 0</rpyOffset>
        <frameName>DiffDriveBase/RearRight/imu_link</frameName>
      </plugin>
      <pose>0 0 0 0 0 0</pose>
    </sensor>
  </gazebo>

  <link name="HEBI_SIM/DiffDriveBase/RearRight/X8_3">
    <visual>
      <origin rpy="  0 0 0" xyz="-0.03 0 0.02"/>
      <geometry>
        <sphere radius="0.001"  />
      </geometry>
    </visual>
    <inertial>
      <mass value="0.001"  />
      <origin rpy="0 0 0" xyz="0 0 0"/>
      <inertia ixx="0.000001"   ixy="0" ixz="0" iyy="0.000001" iyz="0" izz="0.000001"/>
    </inertial>
  </link>
  <joint name="HEBI_SIM_JOINT/DiffDriveBase/RearRight" type="fixed">
    <parent link="DiffDriveBase/RearRight"/>
    <child link="HEBI_SIM/DiffDriveBase/RearRight/X8_3"  />
    <origin rpy="0 0 0" xyz="0 0 0"/>
  </joint>
  <gazebo reference="HEBI_SIM_JOINT/DiffDriveBase/RearRight">
    <disableFixedJointLumping>true</disableFixedJointLumping>
    <preserveFixedJoint>true</preserveFixedJoint>
  </gazebo>

  <link name="pm_2155_01_3">
    <visual>
      <origin rpy="0 0 0" xyz="-0.00099182129 -0.0071643037 -0.000236828"/>
      <geometry>
        <mesh filename="package://stickbot_generated_urdf/meshes/pm_2155_01_prt.stl" scale="0.001 0.001 0.001"/>
      </geometry>
    </visual>
    <collision>
      <origin rpy="0 0 0" xyz="-0.00099182129 -0.0071643037 -0.000236828"/>
      <geometry>
        <mesh filename="package://stickbot_generated_urdf/meshes/pm_2155_01_prt.stl" scale="0.001 0.001 0.001"/>
      </geometry>
    </collision>
    <inertial>
      <origin rpy="0 0 0" xyz="1.34037442317e-07 1.11051366681e-07 0.00499989583184"/>
      <mass value="0.052674179644478125"/>
      <inertia ixx="1.14786537077e-05" ixy="0.0" ixz="0.0" iyy="1.14786271535e-05" iyz="0.0" izz="2.18768701014e-05"/>
    </inertial>
  </link>
  <gazebo reference="pm_2155_01_3">
    <selfCollide>True</selfCollide>
    <material>Gazebo/Grey</material>
    <mu1>0.1</mu1>
    <mu2>0.1</mu2>
    <kp>10000000</kp>
    <kd>1</kd>
    <minDepth>0</minDepth>
    <maxVel>100</maxVel>
  </gazebo>
  <link name="pp_2074_08_2">
    <visual>
      <origin rpy="0 0 0" xyz="7.44914775704e-12 1.23763530372e-11 0.03175"/>
      <geometry>
        <mesh filename="package://stickbot_generated_urdf/meshes/pp_2074_08_prt.stl" scale="0.001 0.001 0.001"/>
      </geometry>
    </visual>
    <collision>
      <origin rpy="0 0 0" xyz="7.44914775704e-12 1.23763530372e-11 0.03175"/>
      <geometry>
        <mesh filename="package://stickbot_generated_urdf/meshes/pp_2074_08_prt.stl" scale="0.001 0.001 0.001"/>
      </geometry>
    </collision>
    <inertial>
      <origin rpy="0 0 0" xyz="-5.78054804372e-07 4.17621039797e-07 0.0190499354094"/>
      <mass value="0.7635860425050807"/>
      <inertia ixx="0.002680677325" ixy="0.0" ixz="0.0" iyy="0.00268067446492" iyz="0.0" izz="0.00527682335031"/>
    </inertial>
  </link>
  <gazebo reference="pp_2074_08_2">
    <selfCollide>True</selfCollide>
    <material>Gazebo/Black</material>
    <mu1>0.7</mu1>
    <mu2>0.7</mu2>
    <kp>1000000</kp>
    <kd>1</kd>
    <minDepth>0.001</minDepth>
    <maxVel>50</maxVel>
  </gazebo>
  <link name="a_2119_01_15Z_0">
    <visual>
      <origin rpy="0 0 0" xyz="-1.387778776e-19 4.89862596425e-19 0.008"/>
      <geometry>
        <mesh filename="package://stickbot_generated_urdf/meshes/a_2119_01_15z_prt.stl" scale="0.001 0.001 0.001"/>
      </geometry>
    </visual>
    <collision>
      <origin rpy="0 0 0" xyz="-1.387778776e-19 4.89862596425e-19 0.008"/>
      <geometry>
        <mesh filename="package://stickbot_generated_urdf/meshes/a_2119_01_15z_prt.stl" scale="0.001 0.001 0.001"/>
      </geometry>
    </collision>
    <inertial>
      <origin rpy="0 0 0" xyz="0.00301190044182 -1.414023009e-07 0.000946994921506"/>
      <mass value="0.10507349679426449"/>
      <inertia ixx="4.21942217795e-05" ixy="0.0" ixz="-1.02460860558e-06" iyy="3.23407137234e-05" iyz="0.0" izz="5.18723516349e-05"/>
    </inertial>
  </link>
  <gazebo reference="a_2119_01_15Z_0">
    <selfCollide>True</selfCollide>
    <material>Gazebo/Grey</material>
    <mu1>0.1</mu1>
    <mu2>0.1</mu2>
    <kp>10000000</kp>
    <kd>1</kd>
    <minDepth>0.0005</minDepth>
    <maxVel>100</maxVel>
  </gazebo>
  <link name="a_2043_01_4">
    <visual>
      <origin rpy="0 0 0" xyz="-2.70533019508e-17 -1.6744411143e-33 0.0047752"/>
      <geometry>
        <mesh filename="package://stickbot_generated_urdf/meshes/a_2043_01_prt.stl" scale="0.001 0.001 0.001"/>
      </geometry>
    </visual>
    <collision>
      <origin rpy="0 0 0" xyz="-2.70533019508e-17 -1.6744411143e-33 0.0047752"/>
      <geometry>
        <mesh filename="package://stickbot_generated_urdf/meshes/a_2043_01_prt.stl" scale="0.001 0.001 0.001"/>
      </geometry>
    </collision>
    <inertial>
      <origin rpy="0 0 0" xyz="0.00139419949295 -1.6744411143e-33 0.00184329510899"/>
      <mass value="0.06272938391183215"/>
      <inertia ixx="7.22571415296e-05" ixy="2.96268938105e-10" ixz="-5.68510520871e-08" iyy="1.34631068457e-05" iyz="0.0" izz="8.48613385518e-05"/>
    </inertial>
  </link>
  <gazebo reference="a_2043_01_4">
    <selfCollide>True</selfCollide>
    <material>Gazebo/Black</material>
    <mu1>0.1</mu1>
    <mu2>0.1</mu2>
    <kp>10000000</kp>
    <kd>1</kd>
    <minDepth>0.0005</minDepth>
    <maxVel>100</maxVel>
  </gazebo>
  <link name="pm_2221_01_2_1">
    <visual>
      <origin rpy="0 0 0" xyz="-3.25941613854e-66 2.64435252763e-34 7.98072809997e-20"/>
      <geometry>
        <mesh filename="package://stickbot_generated_urdf/meshes/pm_2221_01_2_prt.stl" scale="0.001 0.001 0.001"/>
      </geometry>
    </visual>
    <collision>
      <origin rpy="0 0 0" xyz="-3.25941613854e-66 2.64435252763e-34 7.98072809997e-20"/>
      <geometry>
        <mesh filename="package://stickbot_generated_urdf/meshes/pm_2221_01_2_prt.stl" scale="0.001 0.001 0.001"/>
      </geometry>
    </collision>
    <inertial>
      <origin rpy="0 0 0" xyz="0.0135079945905 4.91007296113e-05 7.98072809997e-20"/>
      <mass value="0.007793553528523309"/>
      <inertia ixx="1.38905229874e-07" ixy="5.90681572689e-09" ixz="0.0" iyy="7.98676471223e-07" iyz="0.0" izz="7.51799472482e-07"/>
    </inertial>
  </link>
  <gazebo reference="pm_2221_01_2_1">
    <selfCollide>True</selfCollide>
    <material>Gazebo/Grey</material>
    <mu1>0.05</mu1>
    <mu2>0.05</mu2>
    <kp>10000000</kp>
    <kd>1</kd>
    <minDepth>0.0005</minDepth>
    <maxVel>100</maxVel>
  </gazebo>
  <link name="pm_2371_01_1_1">
    <visual>
      <origin rpy="0 0 0" xyz="0.011 0.011 2.65057264154e-31"/>
      <geometry>
        <mesh filename="package://stickbot_generated_urdf/meshes/pm_2371_01_1_asm.stl" scale="0.001 0.001 0.001"/>
      </geometry>
    </visual>
    <collision>
      <origin rpy="0 0 0" xyz="0.011 0.011 2.65057264154e-31"/>
      <geometry>
        <mesh filename="package://stickbot_generated_urdf/meshes/pm_2371_01_1_asm.stl" scale="0.001 0.001 0.001"/>
      </geometry>
    </collision>
    <inertial>
      <origin rpy="0 0 0" xyz="0.00838478055884 0.0153197434772 2.65057264154e-31"/>
      <mass value="0.036272287461635425"/>
      <inertia ixx="1.302744478e-05" ixy="-5.29971778044e-06" ixz="2.56987932861e-10" iyy="6.68583016907e-06" iyz="-2.14679110174e-10" izz="1.7215751985e-05"/>
    </inertial>
  </link>
  <gazebo reference="pm_2371_01_1_1">
    <selfCollide>True</selfCollide>
    <material>Gazebo/Grey</material>
    <mu1>1.0</mu1>
    <mu2>1.0</mu2>
    <kp>10000000</kp>
    <kd>1</kd>
    <minDepth>0.002</minDepth>
    <maxVel>0</maxVel>
  </gazebo>
  <link name="pm_2371_01_1_0">
    <visual>
      <origin rpy="0 0 0" xyz="0.011 0.011 6.18466949693e-31"/>
      <geometry>
        <mesh filename="package://stickbot_generated_urdf/meshes/pm_2371_01_1_asm.stl" scale="0.001 0.001 0.001"/>
      </geometry>
    </visual>
    <collision>
      <origin rpy="0 0 0" xyz="0.011 0.011 6.18466949693e-31"/>
      <geometry>
        <mesh filename="package://stickbot_generated_urdf/meshes/pm_2371_01_1_asm.stl" scale="0.001 0.001 0.001"/>
      </geometry>
    </collision>
    <inertial>
      <origin rpy="0 0 0" xyz="0.00838478055884 0.0153197434772 6.18466949693e-31"/>
      <mass value="0.036272287461635425"/>
      <inertia ixx="1.302744478e-05" ixy="-5.29971778044e-06" ixz="2.56987932861e-10" iyy="6.68583016907e-06" iyz="-2.14679110174e-10" izz="1.7215751985e-05"/>
    </inertial>
  </link>
  <gazebo reference="pm_2371_01_1_0">
    <selfCollide>True</selfCollide>
    <material>Gazebo/Grey</material>
    <mu1>1.0</mu1>
    <mu2>1.0</mu2>
    <kp>10000000</kp>
    <kd>1</kd>
    <minDepth>0.002</minDepth>
    <maxVel>0</maxVel>
  </gazebo>
  <link name="hebi_x8_16_1Z_0">
    <visual>
      <origin rpy="0 0 0" xyz="-1.56191985342e-17 -1.40834381902e-18 0.023"/>
      <geometry>
        <mesh filename="package://stickbot_generated_urdf/meshes/hebi_x8_16_1z_prt.stl" scale="0.001 0.001 0.001"/>
      </geometry>
    </visual>
    <collision>
      <origin rpy="0 0 0" xyz="-1.56191985342e-17 -1.40834381902e-18 0.023"/>
      <geometry>
        <mesh filename="package://stickbot_generated_urdf/meshes/hebi_x8_16_1z_prt.stl" scale="0.001 0.001 0.001"/>
      </geometry>
    </collision>
    <inertial>
      <origin rpy="0 0 0" xyz="0.014563817146 0.00162514634779 0.0219127754611"/>
      <mass value="5.000268491400921"/>
      <inertia ixx="0.00252497997304" ixy="-0.000307494501523" ixz="2.34381592723e-05" iyy="0.00412897878772" iyz="6.0494430943e-06" izz="0.0050506140471"/>
    </inertial>
  </link>
  <gazebo reference="hebi_x8_16_1Z_0">
    <selfCollide>True</selfCollide>
    <material>Gazebo/Red</material>
    <mu1>0.1</mu1>
    <mu2>0.1</mu2>
    <kp>10000000</kp>
    <kd>1</kd>
    <minDepth>0.001</minDepth>
    <maxVel>100</maxVel>
    <sensor name="DiffDriveBase/FrontRight/imu_sensor" type="imu">
      <always_on>true</always_on>
      <update_rate>100</update_rate>
      <visualize>true</visualize>
      <plugin filename="libgazebo_ros_imu_sensor.so" name="imu_plugin">
        <topicName>/hebiros_gazebo_plugin/imu/DiffDriveBase/FrontRight</topicName>
        <bodyName>DiffDriveBase/FrontRight/imu_link</bodyName>
        <updateRateHZ>10.0</updateRateHZ>
        <gaussianNoise>0.0</gaussianNoise>
        <xyzOffset>0.025 0 0.003</xyzOffset>
        <rpyOffset>0 0 0</rpyOffset>
        <frameName>DiffDriveBase/FrontRight/imu_link</frameName>
      </plugin>
      <pose>0 0 0 0 0 0</pose>
    </sensor>
  </gazebo>
  <link name="a_2043_01_0">
    <visual>
      <origin rpy="0 0 0" xyz="-2.68108607925e-17 -1.65959587488e-33 0.0047752"/>
      <geometry>
        <mesh filename="package://stickbot_generated_urdf/meshes/a_2043_01_prt.stl" scale="0.001 0.001 0.001"/>
      </geometry>
    </visual>
    <collision>
      <origin rpy="0 0 0" xyz="-2.68108607925e-17 -1.65959587488e-33 0.0047752"/>
      <geometry>
        <mesh filename="package://stickbot_generated_urdf/meshes/a_2043_01_prt.stl" scale="0.001 0.001 0.001"/>
      </geometry>
    </collision>
    <inertial>
      <origin rpy="0 0 0" xyz="0.00139419949295 -1.65959587488e-33 0.00184329510899"/>
      <mass value="0.06272938391183215"/>
      <inertia ixx="7.22571415296e-05" ixy="2.96268938105e-10" ixz="-5.68510520871e-08" iyy="1.34631068457e-05" iyz="0.0" izz="8.48613385518e-05"/>
    </inertial>
  </link>
  <gazebo reference="a_2043_01_0">
    <selfCollide>True</selfCollide>
    <material>Gazebo/Black</material>
    <mu1>0.1</mu1>
    <mu2>0.1</mu2>
    <kp>10000000</kp>
    <kd>1</kd>
    <minDepth>0.0005</minDepth>
    <maxVel>100</maxVel>
  </gazebo>
  <link name="pp_2084_01_1">
    <visual>
      <origin rpy="0 0 0" xyz="-6.12323396889e-24 -8.54233987271e-57 2.18641211966e-40"/>
      <geometry>
        <mesh filename="package://stickbot_generated_urdf/meshes/pp_2084_01_prt.stl" scale="0.001 0.001 0.001"/>
      </geometry>
    </visual>
    <collision>
      <origin rpy="0 0 0" xyz="-6.12323396889e-24 -8.54233987271e-57 2.18641211966e-40"/>
      <geometry>
        <mesh filename="package://stickbot_generated_urdf/meshes/pp_2084_01_prt.stl" scale="0.001 0.001 0.001"/>
      </geometry>
    </collision>
    <inertial>
      <origin rpy="0 0 0" xyz="8.91874378258e-05 1.84543304597e-05 0.0105126561021"/>
      <mass value="0.6195229072329779"/>
      <inertia ixx="0.000303103586737" ixy="1.97180265393e-06" ixz="0.0" iyy="0.00207546071735" iyz="8.31436607584e-09" izz="0.00233313205399"/>
    </inertial>
  </link>
  <gazebo reference="pp_2084_01_1">
    <selfCollide>True</selfCollide>
    <material>Gazebo/Black</material>
    <mu1>0.1</mu1>
    <mu2>0.1</mu2>
    <kp>10000000</kp>
    <kd>1</kd>
    <minDepth>0.0005</minDepth>
    <maxVel>100</maxVel>
  </gazebo>
  <link name="tubepar_19Z_0">
    <visual>
      <origin rpy="0 0 0" xyz="2.01948391737e-31 -0.5 0.0"/>
      <geometry>
        <mesh filename="package://stickbot_generated_urdf/meshes/tubepar_19z_prt.stl" scale="0.001 0.001 0.001"/>
      </geometry>
    </visual>
    <collision>
      <origin rpy="0 0 0" xyz="2.01948391737e-31 -0.5 0.0"/>
      <geometry>
        <mesh filename="package://stickbot_generated_urdf/meshes/tubepar_19z_prt.stl" scale="0.001 0.001 0.001"/>
      </geometry>
    </collision>
    <inertial>
      <origin rpy="0 0 0" xyz="2.01948391737e-31 -0.25 0.0"/>
      <mass value="0.2022237879860671"/>
      <inertia ixx="0.00423586331341" ixy="0.0" ixz="0.0" iyy="4.57355090629e-05" iyz="0.0" izz="0.00423586336174"/>
    </inertial>
  </link>
  <gazebo reference="tubepar_19Z_0">
    <selfCollide>True</selfCollide>
    <material>Gazebo/Grey</material>
    <mu1>0.05</mu1>
    <mu2>0.05</mu2>
    <kp>10000000</kp>
    <kd>1</kd>
    <minDepth>0.0005</minDepth>
    <maxVel>100</maxVel>
  </gazebo>
  <link name="hebi_x8_16_12Z_0">
    <visual>
      <origin rpy="0 0 0" xyz="-2.72157547031e-32 -1.40835994225e-18 0.023"/>
      <geometry>
        <mesh filename="package://stickbot_generated_urdf/meshes/hebi_x8_16_12z_prt.stl" scale="0.001 0.001 0.001"/>
      </geometry>
    </visual>
    <collision>
      <origin rpy="0 0 0" xyz="-2.72157547031e-32 -1.40835994225e-18 0.023"/>
      <geometry>
        <mesh filename="package://stickbot_generated_urdf/meshes/hebi_x8_16_12z_prt.stl" scale="0.001 0.001 0.001"/>
      </geometry>
    </collision>
    <inertial>
      <origin rpy="0 0 0" xyz="0.014563817146 0.00162514634779 0.0219127754611"/>
      <mass value="5.000268491400921"/>
      <inertia ixx="0.00252497997304" ixy="-0.000307494501523" ixz="2.34381592723e-05" iyy="0.00412897878772" iyz="6.0494430943e-06" izz="0.0050506140471"/>
    </inertial>
  </link>
  <gazebo reference="hebi_x8_16_12Z_0">
    <selfCollide>True</selfCollide>
    <material>Gazebo/Red</material>
    <mu1>0.1</mu1>
    <mu2>0.1</mu2>
    <kp>10000000</kp>
    <kd>1</kd>
    <minDepth>0.001</minDepth>
    <maxVel>100</maxVel>
    <sensor name="Arm/Shoulder/imu_sensor" type="imu">
      <always_on>true</always_on>
      <update_rate>100</update_rate>
      <visualize>true</visualize>
      <plugin filename="libgazebo_ros_imu_sensor.so" name="imu_plugin">
        <topicName>/hebiros_gazebo_plugin/imu/Arm/Shoulder</topicName>
        <bodyName>Arm/Shoulder/imu_link</bodyName>
        <updateRateHZ>10.0</updateRateHZ>
        <gaussianNoise>0.0</gaussianNoise>
        <xyzOffset>0.025 0 0.003</xyzOffset>
        <rpyOffset>0 0 0</rpyOffset>
        <frameName>Arm/Shoulder/imu_link</frameName>
      </plugin>
      <pose>0 0 0 0 0 0</pose>
    </sensor>
  </gazebo>
  <link name="rplidar_a2_0">
    <visual>
      <origin rpy="0 0 0" xyz="5.79300502416e-24 3.54719253014e-40 1.91946740777e-38"/>
      <geometry>
        <mesh filename="package://stickbot_generated_urdf/meshes/rplidar_a2_asm.stl" scale="0.001 0.001 0.001"/>
      </geometry>
    </visual>
    <collision>
      <origin rpy="0 0 0" xyz="5.79300502416e-24 3.54719253014e-40 1.91946740777e-38"/>
      <geometry>
        <mesh filename="package://stickbot_generated_urdf/meshes/rplidar_a2_asm.stl" scale="0.001 0.001 0.001"/>
      </geometry>
    </collision>
    <inertial>
      <origin rpy="0 0 0" xyz="-0.000130340672722 -0.00136533102019 0.0205166626404"/>
      <mass value="0.18821621589950202"/>
      <inertia ixx="8.13361235458e-05" ixy="-2.24566593777e-07" ixz="7.5260897031e-09" iyy="7.83925013627e-05" iyz="2.44355055998e-06" izz="0.000134676697915"/>
    </inertial>
  </link>
  <gazebo reference="rplidar_a2_0">
    <selfCollide>True</selfCollide>
    <material>Gazebo/Black</material>
    <mu1>0.05</mu1>
    <mu2>0.05</mu2>
    <kp>10000000</kp>
    <kd>1</kd>
    <minDepth>0.0005</minDepth>
    <maxVel>100</maxVel>
  </gazebo>
  <link name="a_2038_02_17Z_0">
    <visual>
      <origin rpy="0 0 0" xyz="-3.69026236889e-34 1.11373125466e-19 6.40158474177e-51"/>
      <geometry>
        <mesh filename="package://stickbot_generated_urdf/meshes/a_2038_02_17z_prt.stl" scale="0.001 0.001 0.001"/>
      </geometry>
    </visual>
    <collision>
      <origin rpy="0 0 0" xyz="-3.69026236889e-34 1.11373125466e-19 6.40158474177e-51"/>
      <geometry>
        <mesh filename="package://stickbot_generated_urdf/meshes/a_2038_02_17z_prt.stl" scale="0.001 0.001 0.001"/>
      </geometry>
    </collision>
    <inertial>
      <origin rpy="0 0 0" xyz="0.0176052907699 1.11373125466e-19 0.0142788404199"/>
      <mass value="0.059108249978877175"/>
      <inertia ixx="2.3632587043e-05" ixy="0.0" ixz="-3.93131579939e-06" iyy="2.03298829586e-05" iyz="0.0" izz="2.72912531732e-05"/>
    </inertial>
  </link>
  <gazebo reference="a_2038_02_17Z_0">
    <selfCollide>True</selfCollide>
    <material>Gazebo/Black</material>
    <mu1>0.1</mu1>
    <mu2>0.1</mu2>
    <kp>10000000</kp>
    <kd>1</kd>
    <minDepth>0.0005</minDepth>
    <maxVel>100</maxVel>
  </gazebo>
  <link name="pm_2221_01_2_0">
    <visual>
      <origin rpy="0 0 0" xyz="3.25859931682e-66 2.64368984312e-34 -7.97872810003e-20"/>
      <geometry>
        <mesh filename="package://stickbot_generated_urdf/meshes/pm_2221_01_2_prt.stl" scale="0.001 0.001 0.001"/>
      </geometry>
    </visual>
    <collision>
      <origin rpy="0 0 0" xyz="3.25859931682e-66 2.64368984312e-34 -7.97872810003e-20"/>
      <geometry>
        <mesh filename="package://stickbot_generated_urdf/meshes/pm_2221_01_2_prt.stl" scale="0.001 0.001 0.001"/>
      </geometry>
    </collision>
    <inertial>
      <origin rpy="0 0 0" xyz="0.0135079945905 4.91007296113e-05 -7.97872810003e-20"/>
      <mass value="0.007793553528523309"/>
      <inertia ixx="1.38905229874e-07" ixy="5.90681572689e-09" ixz="0.0" iyy="7.98676471223e-07" iyz="0.0" izz="7.51799472482e-07"/>
    </inertial>
  </link>
  <gazebo reference="pm_2221_01_2_0">
    <selfCollide>True</selfCollide>
    <material>Gazebo/Grey</material>
    <mu1>0.05</mu1>
    <mu2>0.05</mu2>
    <kp>10000000</kp>
    <kd>1</kd>
    <minDepth>0.0005</minDepth>
    <maxVel>100</maxVel>
  </gazebo>
  <link name="pp_2074_08_0">
    <visual>
      <origin rpy="0 0 0" xyz="1.37817935453e-11 1.92220120108e-11 0.03175"/>
      <geometry>
        <mesh filename="package://stickbot_generated_urdf/meshes/pp_2074_08_prt.stl" scale="0.001 0.001 0.001"/>
      </geometry>
    </visual>
    <collision>
      <origin rpy="0 0 0" xyz="1.37817935453e-11 1.92220120108e-11 0.03175"/>
      <geometry>
        <mesh filename="package://stickbot_generated_urdf/meshes/pp_2074_08_prt.stl" scale="0.001 0.001 0.001"/>
      </geometry>
    </collision>
    <inertial>
      <origin rpy="0 0 0" xyz="-5.78048471727e-07 4.17627885456e-07 0.0190499354094"/>
      <mass value="0.7635860425050807"/>
      <inertia ixx="0.002680677325" ixy="0.0" ixz="0.0" iyy="0.00268067446492" iyz="0.0" izz="0.00527682335031"/>
    </inertial>
  </link>
  <gazebo reference="pp_2074_08_0">
    <selfCollide>True</selfCollide>
    <material>Gazebo/Black</material>
    <mu1>0.7</mu1>
    <mu2>0.7</mu2>
    <kp>1000000</kp>
    <kd>1</kd>
    <minDepth>0.001</minDepth>
    <maxVel>50</maxVel>
  </gazebo>
  <link name="hebi_x8_16_16Z_0">
    <visual>
      <origin rpy="0 0 0" xyz="-1.56191985342e-17 1.40700203333e-16 0.023"/>
      <geometry>
        <mesh filename="package://stickbot_generated_urdf/meshes/hebi_x8_16_16z_prt.stl" scale="0.001 0.001 0.001"/>
      </geometry>
    </visual>
    <collision>
      <origin rpy="0 0 0" xyz="-1.56191985342e-17 1.40700203333e-16 0.023"/>
      <geometry>
        <mesh filename="package://stickbot_generated_urdf/meshes/hebi_x8_16_16z_prt.stl" scale="0.001 0.001 0.001"/>
      </geometry>
    </collision>
    <inertial>
      <origin rpy="0 0 0" xyz="0.014563817146 0.00162514634779 0.0219127754611"/>
      <mass value="5.000268491400921"/>
      <inertia ixx="0.00252497997304" ixy="-0.000307494501523" ixz="2.34381592723e-05" iyy="0.00412897878772" iyz="6.0494430943e-06" izz="0.0050506140471"/>
    </inertial>
  </link>
  <gazebo reference="hebi_x8_16_16Z_0">
    <selfCollide>True</selfCollide>
    <material>Gazebo/Red</material>
    <mu1>0.1</mu1>
    <mu2>0.1</mu2>
    <kp>10000000</kp>
    <kd>1</kd>
    <minDepth>0.001</minDepth>
    <maxVel>100</maxVel>
    <sensor name="DiffDriveBase/RearLeft/imu_sensor" type="imu">
      <always_on>true</always_on>
      <update_rate>100</update_rate>
      <visualize>true</visualize>
      <plugin filename="libgazebo_ros_imu_sensor.so" name="imu_plugin">
        <topicName>/hebiros_gazebo_plugin/imu/DiffDriveBase/RearLeft</topicName>
        <bodyName>DiffDriveBase/RearLeft/imu_link</bodyName>
        <updateRateHZ>10.0</updateRateHZ>
        <gaussianNoise>0.0</gaussianNoise>
        <xyzOffset>0.025 0 0.003</xyzOffset>
        <rpyOffset>0 0 0</rpyOffset>
        <frameName>DiffDriveBase/RearLeft/imu_link</frameName>
      </plugin>
      <pose>0 0 0 0 0 0</pose>
    </sensor>
  </gazebo>
  <link name="a_2132_01_5Z_0">
    <visual>
      <origin rpy="0 0 0" xyz="1e-23 1e-23 1e-23"/>
      <geometry>
        <mesh filename="package://stickbot_generated_urdf/meshes/a_2132_01_5z_asm.stl" scale="0.001 0.001 0.001"/>
      </geometry>
    </visual>
    <collision>
      <origin rpy="0 0 0" xyz="1e-23 1e-23 1e-23"/>
      <geometry>
        <mesh filename="package://stickbot_generated_urdf/meshes/a_2132_01_5z_asm.stl" scale="0.001 0.001 0.001"/>
      </geometry>
    </collision>
    <inertial>
      <origin rpy="0 0 0" xyz="-0.00104257046574 -3.13779178833e-05 0.0205056292804"/>
      <mass value="7.508721473887056"/>
      <inertia ixx="0.116377534988" ixy="4.10977062061e-05" ixz="0.000493457266438" iyy="0.120778948593" iyz="0.000316792898742" izz="0.214005834039"/>
    </inertial>
  </link>
  <gazebo reference="a_2132_01_5Z_0">
    <selfCollide>True</selfCollide>
    <material>Gazebo/Grey</material>
    <mu1>0.1</mu1>
    <mu2>0.1</mu2>
    <kp>10000000</kp>
    <kd>1</kd>
    <minDepth>0.0005</minDepth>
    <maxVel>100</maxVel>
  </gazebo>
  <link name="hebi_x5_9_7Z_0">
    <visual>
      <origin rpy="0 0 0" xyz="-1.561251135e-19 -1.57950058741e-18 0.015"/>
      <geometry>
        <mesh filename="package://stickbot_generated_urdf/meshes/hebi_x5_9_7z_prt.stl" scale="0.001 0.001 0.001"/>
      </geometry>
    </visual>
    <collision>
      <origin rpy="0 0 0" xyz="-1.561251135e-19 -1.57950058741e-18 0.015"/>
      <geometry>
        <mesh filename="package://stickbot_generated_urdf/meshes/hebi_x5_9_7z_prt.stl" scale="0.001 0.001 0.001"/>
      </geometry>
    </collision>
    <inertial>
      <origin rpy="0 0 0" xyz="-0.0142019322139 -0.00151173442654 0.0150064707722"/>
      <mass value="0.3601223934133934"/>
      <inertia ixx="0.000149654657264" ixy="-2.029262623e-05" ixz="1.36324075072e-08" iyy="0.000259599603648" iyz="1.37817063293e-07" izz="0.000355190384437"/>
    </inertial>
  </link>
  <gazebo reference="hebi_x5_9_7Z_0">
    <selfCollide>True</selfCollide>
    <material>Gazebo/Red</material>
    <mu1>0.1</mu1>
    <mu2>0.1</mu2>
    <kp>10000000</kp>
    <kd>1</kd>
    <minDepth>0.001</minDepth>
    <maxVel>100</maxVel>
    <sensor name="Gripper/Spool/imu_sensor" type="imu">
      <always_on>true</always_on>
      <update_rate>100</update_rate>
      <visualize>true</visualize>
      <plugin filename="libgazebo_ros_imu_sensor.so" name="imu_plugin">
        <topicName>/hebiros_gazebo_plugin/imu/Gripper/Spool</topicName>
        <bodyName>Gripper/Spool/imu_link</bodyName>
        <updateRateHZ>10.0</updateRateHZ>
        <gaussianNoise>0.0</gaussianNoise>
        <xyzOffset>0.025 0 0.003</xyzOffset>
        <rpyOffset>0 0 0</rpyOffset>
        <frameName>Gripper/Spool/imu_link</frameName>
      </plugin>
      <pose>0 0 0 0 0 0</pose>
    </sensor>
  </gazebo>
  <link name="hebi_x8_16_2Z_0">
    <visual>
      <origin rpy="0 0 0" xyz="-1.56191985342e-17 -1.43516890971e-16 0.023"/>
      <geometry>
        <mesh filename="package://stickbot_generated_urdf/meshes/hebi_x8_16_2z_prt.stl" scale="0.001 0.001 0.001"/>
      </geometry>
    </visual>
    <collision>
      <origin rpy="0 0 0" xyz="-1.56191985342e-17 -1.43516890971e-16 0.023"/>
      <geometry>
        <mesh filename="package://stickbot_generated_urdf/meshes/hebi_x8_16_2z_prt.stl" scale="0.001 0.001 0.001"/>
      </geometry>
    </collision>
    <inertial>
      <origin rpy="0 0 0" xyz="0.014563817146 0.00162514634779 0.0219127754611"/>
      <mass value="5.000268491400921"/>
      <inertia ixx="0.00252497997304" ixy="-0.000307494501523" ixz="2.34381592723e-05" iyy="0.00412897878772" iyz="6.0494430943e-06" izz="0.0050506140471"/>
    </inertial>
  </link>
  <gazebo reference="hebi_x8_16_2Z_0">
    <selfCollide>True</selfCollide>
    <material>Gazebo/Red</material>
    <mu1>0.1</mu1>
    <mu2>0.1</mu2>
    <kp>10000000</kp>
    <kd>1</kd>
    <minDepth>0.001</minDepth>
    <maxVel>100</maxVel>
    <sensor name="DiffDriveBase/FrontLeft/imu_sensor" type="imu">
      <always_on>true</always_on>
      <update_rate>100</update_rate>
      <visualize>true</visualize>
      <plugin filename="libgazebo_ros_imu_sensor.so" name="imu_plugin">
        <topicName>/hebiros_gazebo_plugin/imu/DiffDriveBase/FrontLeft</topicName>
        <bodyName>DiffDriveBase/FrontLeft/imu_link</bodyName>
        <updateRateHZ>10.0</updateRateHZ>
        <gaussianNoise>0.0</gaussianNoise>
        <xyzOffset>0.025 0 0.003</xyzOffset>
        <rpyOffset>0 0 0</rpyOffset>
        <frameName>DiffDriveBase/FrontLeft/imu_link</frameName>
      </plugin>
      <pose>0 0 0 0 0 0</pose>
    </sensor>
  </gazebo>
  <link name="pm_2155_01_2">
    <visual>
      <origin rpy="0 0 0" xyz="-0.00099182129 -0.0071643037 -0.000236828"/>
      <geometry>
        <mesh filename="package://stickbot_generated_urdf/meshes/pm_2155_01_prt.stl" scale="0.001 0.001 0.001"/>
      </geometry>
    </visual>
    <collision>
      <origin rpy="0 0 0" xyz="-0.00099182129 -0.0071643037 -0.000236828"/>
      <geometry>
        <mesh filename="package://stickbot_generated_urdf/meshes/pm_2155_01_prt.stl" scale="0.001 0.001 0.001"/>
      </geometry>
    </collision>
    <inertial>
      <origin rpy="0 0 0" xyz="1.34037442318e-07 1.11051366582e-07 0.00499989583184"/>
      <mass value="0.052674179644478125"/>
      <inertia ixx="1.14786537077e-05" ixy="0.0" ixz="0.0" iyy="1.14786271535e-05" iyz="0.0" izz="2.18768701014e-05"/>
    </inertial>
  </link>
  <gazebo reference="pm_2155_01_2">
    <selfCollide>True</selfCollide>
    <material>Gazebo/Grey</material>
    <mu1>0.1</mu1>
    <mu2>0.1</mu2>
    <kp>10000000</kp>
    <kd>1</kd>
    <minDepth>0</minDepth>
    <maxVel>100</maxVel>
  </gazebo>
  <link name="a_2043_01_1">
    <visual>
      <origin rpy="0 0 0" xyz="4.67700711639e-17 9.38208807873e-16 0.0047752"/>
      <geometry>
        <mesh filename="package://stickbot_generated_urdf/meshes/a_2043_01_prt.stl" scale="0.001 0.001 0.001"/>
      </geometry>
    </visual>
    <collision>
      <origin rpy="0 0 0" xyz="4.67700711639e-17 9.38208807873e-16 0.0047752"/>
      <geometry>
        <mesh filename="package://stickbot_generated_urdf/meshes/a_2043_01_prt.stl" scale="0.001 0.001 0.001"/>
      </geometry>
    </collision>
    <inertial>
      <origin rpy="0 0 0" xyz="0.00139419949295 9.38208807873e-16 0.00184329510899"/>
      <mass value="0.06272938391183215"/>
      <inertia ixx="7.22571415296e-05" ixy="2.96268938105e-10" ixz="-5.68510520871e-08" iyy="1.34631068457e-05" iyz="0.0" izz="8.48613385518e-05"/>
    </inertial>
  </link>
  <gazebo reference="a_2043_01_1">
    <selfCollide>True</selfCollide>
    <material>Gazebo/Black</material>
    <mu1>0.1</mu1>
    <mu2>0.1</mu2>
    <kp>10000000</kp>
    <kd>1</kd>
    <minDepth>0.0005</minDepth>
    <maxVel>100</maxVel>
  </gazebo>
  <link name="a_2043_01_5">
    <visual>
      <origin rpy="0 0 0" xyz="-2.96792033927e-18 8.5557524961e-17 0.0047752"/>
      <geometry>
        <mesh filename="package://stickbot_generated_urdf/meshes/a_2043_01_prt.stl" scale="0.001 0.001 0.001"/>
      </geometry>
    </visual>
    <collision>
      <origin rpy="0 0 0" xyz="-2.96792033927e-18 8.5557524961e-17 0.0047752"/>
      <geometry>
        <mesh filename="package://stickbot_generated_urdf/meshes/a_2043_01_prt.stl" scale="0.001 0.001 0.001"/>
      </geometry>
    </collision>
    <inertial>
      <origin rpy="0 0 0" xyz="0.00139419949295 8.5557524961e-17 0.00184329510899"/>
      <mass value="0.06272938391183215"/>
      <inertia ixx="7.22571415296e-05" ixy="2.96268938105e-10" ixz="-5.68510520871e-08" iyy="1.34631068457e-05" iyz="0.0" izz="8.48613385518e-05"/>
    </inertial>
  </link>
  <gazebo reference="a_2043_01_5">
    <selfCollide>True</selfCollide>
    <material>Gazebo/Black</material>
    <mu1>0.1</mu1>
    <mu2>0.1</mu2>
    <kp>10000000</kp>
    <kd>1</kd>
    <minDepth>0.0005</minDepth>
    <maxVel>100</maxVel>
  </gazebo>
  <link name="pp_2084_01_0">
    <visual>
      <origin rpy="0 0 0" xyz="8.12402960042e-19 1.13335897886e-51 -2.90083261052e-35"/>
      <geometry>
        <mesh filename="package://stickbot_generated_urdf/meshes/pp_2084_01_prt.stl" scale="0.001 0.001 0.001"/>
      </geometry>
    </visual>
    <collision>
      <origin rpy="0 0 0" xyz="8.12402960042e-19 1.13335897886e-51 -2.90083261052e-35"/>
      <geometry>
        <mesh filename="package://stickbot_generated_urdf/meshes/pp_2084_01_prt.stl" scale="0.001 0.001 0.001"/>
      </geometry>
    </collision>
    <inertial>
      <origin rpy="0 0 0" xyz="8.91874378258e-05 1.84543304597e-05 0.0105126561021"/>
      <mass value="0.6195229072329779"/>
      <inertia ixx="0.000303103586737" ixy="1.97180265393e-06" ixz="0.0" iyy="0.00207546071735" iyz="8.31436607584e-09" izz="0.00233313205399"/>
    </inertial>
  </link>
  <gazebo reference="pp_2084_01_0">
    <selfCollide>True</selfCollide>
    <material>Gazebo/Black</material>
    <mu1>0.1</mu1>
    <mu2>0.1</mu2>
    <kp>10000000</kp>
    <kd>1</kd>
    <minDepth>0.0005</minDepth>
    <maxVel>100</maxVel>
  </gazebo>
  <link name="a_2039_02_9Z_0">
    <visual>
      <origin rpy="0 0 0" xyz="0.014 3.4788792385e-16 0.02"/>
      <geometry>
        <mesh filename="package://stickbot_generated_urdf/meshes/a_2039_02_9z_prt.stl" scale="0.001 0.001 0.001"/>
      </geometry>
    </visual>
    <collision>
      <origin rpy="0 0 0" xyz="0.014 3.4788792385e-16 0.02"/>
      <geometry>
        <mesh filename="package://stickbot_generated_urdf/meshes/a_2039_02_9z_prt.stl" scale="0.001 0.001 0.001"/>
      </geometry>
    </collision>
    <inertial>
      <origin rpy="0 0 0" xyz="0.00256411047128 3.4788792385e-16 0.00833404763152"/>
      <mass value="0.08075605008850124"/>
      <inertia ixx="3.54766366127e-05" ixy="0.0" ixz="-8.29679742245e-06" iyy="3.7139980371e-05" iyz="0.0" izz="5.23238184568e-05"/>
    </inertial>
  </link>
  <gazebo reference="a_2039_02_9Z_0">
    <selfCollide>True</selfCollide>
    <material>Gazebo/Black</material>
    <mu1>0.1</mu1>
    <mu2>0.1</mu2>
    <kp>10000000</kp>
    <kd>1</kd>
    <minDepth>0.0005</minDepth>
    <maxVel>100</maxVel>
  </gazebo>
  <link name="a_2043_01_3">
    <visual>
      <origin rpy="0 0 0" xyz="4.67700711639e-17 -9.37624014534e-16 0.0047752"/>
      <geometry>
        <mesh filename="package://stickbot_generated_urdf/meshes/a_2043_01_prt.stl" scale="0.001 0.001 0.001"/>
      </geometry>
    </visual>
    <collision>
      <origin rpy="0 0 0" xyz="4.67700711639e-17 -9.37624014534e-16 0.0047752"/>
      <geometry>
        <mesh filename="package://stickbot_generated_urdf/meshes/a_2043_01_prt.stl" scale="0.001 0.001 0.001"/>
      </geometry>
    </collision>
    <inertial>
      <origin rpy="0 0 0" xyz="0.00139419949295 -9.37624014534e-16 0.00184329510899"/>
      <mass value="0.06272938391183215"/>
      <inertia ixx="7.22571415296e-05" ixy="2.96268938105e-10" ixz="-5.68510520871e-08" iyy="1.34631068457e-05" iyz="0.0" izz="8.48613385518e-05"/>
    </inertial>
  </link>
  <gazebo reference="a_2043_01_3">
    <selfCollide>True</selfCollide>
    <material>Gazebo/Black</material>
    <mu1>0.1</mu1>
    <mu2>0.1</mu2>
    <kp>10000000</kp>
    <kd>1</kd>
    <minDepth>0.0005</minDepth>
    <maxVel>100</maxVel>
  </gazebo>
  <link name="tubepar_4Z_0">
    <visual>
      <origin rpy="0 0 0" xyz="-2.18952885051e-47 -0.25 -1.61232339545e-23"/>
      <geometry>
        <mesh filename="package://stickbot_generated_urdf/meshes/tubepar_4z_prt.stl" scale="0.001 0.001 0.001"/>
      </geometry>
    </visual>
    <collision>
      <origin rpy="0 0 0" xyz="-2.18952885051e-47 -0.25 -1.61232339545e-23"/>
      <geometry>
        <mesh filename="package://stickbot_generated_urdf/meshes/tubepar_4z_prt.stl" scale="0.001 0.001 0.001"/>
      </geometry>
    </collision>
    <inertial>
      <origin rpy="0 0 0" xyz="-2.18952885051e-47 -0.125 -1.61232339545e-23"/>
      <mass value="0.10111189399303355"/>
      <inertia ixx="0.000538058313062" ixy="0.0" ixz="0.0" iyy="2.28677545314e-05" iyz="0.0" izz="0.00053805833723"/>
    </inertial>
  </link>
  <gazebo reference="tubepar_4Z_0">
    <selfCollide>True</selfCollide>
    <material>Gazebo/Grey</material>
    <mu1>0.05</mu1>
    <mu2>0.05</mu2>
    <kp>10000000</kp>
    <kd>1</kd>
    <minDepth>0.0005</minDepth>
    <maxVel>100</maxVel>
  </gazebo>
  <link name="a_2089_01_14Z_0">
    <visual>
      <origin rpy="0 0 0" xyz="-0.014 -1.07158121718e-18 -0.0175"/>
      <geometry>
        <mesh filename="package://stickbot_generated_urdf/meshes/a_2089_01_14z_prt.stl" scale="0.001 0.001 0.001"/>
      </geometry>
    </visual>
    <collision>
      <origin rpy="0 0 0" xyz="-0.014 -1.07158121718e-18 -0.0175"/>
      <geometry>
        <mesh filename="package://stickbot_generated_urdf/meshes/a_2089_01_14z_prt.stl" scale="0.001 0.001 0.001"/>
      </geometry>
    </collision>
    <inertial>
      <origin rpy="0 0 0" xyz="-0.0141834319891 1.2390345004e-07 -0.00675469816879"/>
      <mass value="0.13694950430241026"/>
      <inertia ixx="6.44476746049e-05" ixy="0.0" ixz="2.64849744516e-08" iyy="8.71842240473e-05" iyz="0.0" izz="0.000115762185767"/>
    </inertial>
  </link>
  <gazebo reference="a_2089_01_14Z_0">
    <selfCollide>True</selfCollide>
    <material>Gazebo/Grey</material>
    <mu1>0.1</mu1>
    <mu2>0.1</mu2>
    <kp>10000000</kp>
    <kd>1</kd>
    <minDepth>0.0005</minDepth>
    <maxVel>100</maxVel>
  </gazebo>
  <link name="hebi_x8_16_20Z_0">
    <visual>
      <origin rpy="0 0 0" xyz="-1.38777827631e-17 -3.7137370742e-32 0.023"/>
      <geometry>
        <mesh filename="package://stickbot_generated_urdf/meshes/hebi_x8_16_20z_prt.stl" scale="0.001 0.001 0.001"/>
      </geometry>
    </visual>
    <collision>
      <origin rpy="0 0 0" xyz="-1.38777827631e-17 -3.7137370742e-32 0.023"/>
      <geometry>
        <mesh filename="package://stickbot_generated_urdf/meshes/hebi_x8_16_20z_prt.stl" scale="0.001 0.001 0.001"/>
      </geometry>
    </collision>
    <inertial>
      <origin rpy="0 0 0" xyz="0.014563817146 0.00162514634779 0.0219127754611"/>
      <mass value="5.000268491400921"/>
      <inertia ixx="0.00252497997304" ixy="-0.000307494501523" ixz="2.34381592723e-05" iyy="0.00412897878772" iyz="6.0494430943e-06" izz="0.0050506140471"/>
    </inertial>
  </link>
  <gazebo reference="hebi_x8_16_20Z_0">
    <selfCollide>True</selfCollide>
    <material>Gazebo/Red</material>
    <mu1>0.1</mu1>
    <mu2>0.1</mu2>
    <kp>10000000</kp>
    <kd>1</kd>
    <minDepth>0.001</minDepth>
    <maxVel>100</maxVel>
    <sensor name="Turret/Base/imu_sensor" type="imu">
      <always_on>true</always_on>
      <update_rate>100</update_rate>
      <visualize>true</visualize>
      <plugin filename="libgazebo_ros_imu_sensor.so" name="imu_plugin">
        <topicName>/hebiros_gazebo_plugin/imu/Turret/Base</topicName>
        <bodyName>Turret/Base/imu_link</bodyName>
        <updateRateHZ>10.0</updateRateHZ>
        <gaussianNoise>0.0</gaussianNoise>
        <xyzOffset>0.025 0 0.003</xyzOffset>
        <rpyOffset>0 0 0</rpyOffset>
        <frameName>Turret/Base/imu_link</frameName>
      </plugin>
      <pose>0 0 0 0 0 0</pose>
    </sensor>
  </gazebo>
  <!--HEBI-ROS Gazebo Plugin-->
  <gazebo>
    <plugin filename="libhebi_gazebo_plugin.so" name="hebi_gazebo_plugin"  />
  </gazebo>
</robot>
